Workbook
Name Rate_Basic: Rates!$B$2
Name Rate_Higher: Rates!$B$3
Name Rate_Additional: Rates!$B$4
Name Reducer_2026: Rates!$B$5
Name Reducer_2027: Rates!$B$6
Name CGT_AEA: Rates!$B$7
Name CGT_Basic: Rates!$B$8
Name CGT_Higher: Rates!$B$9
Name SDLT_Surcharge: Rates!$B$10
Name CT_Small: Rates!$B$11
Name CT_Main: Rates!$B$12
Name CT_Lower: Rates!$B$13
Name CT_Upper: Rates!$B$14
Name CT_Fraction: Rates!$B$15
Name Div_Basic: Rates!$B$16
Name Div_Higher: Rates!$B$17
Name Div_Additional: Rates!$B$18
Name SDLT_Lowers: Rates!$A$22:$A$26
Name SDLT_Uppers: Rates!$B$22:$B$26
Name SDLT_Rates: Rates!$C$22:$C$26
Name PersonalAllowance: Rates!$B$28
Name BasicRateBand: Rates!$B$29
Name DividendAllowance: Rates!$B$30
Name BasicRateTop: Rates!$B$31
Name HigherRateTop: Rates!$B$32
Name In_Value: 'Your figures'!$B$3
Name In_Base: 'Your figures'!$B$4
Name In_Costs: 'Your figures'!$B$5
Name In_Rent: 'Your figures'!$B$6
Name In_Interest: 'Your figures'!$B$7
Name In_Other: 'Your figures'!$B$8
Name In_OtherIncome: 'Your figures'!$B$9
Name In_Band: 'Your figures'!$B$10
Name In_Year: 'Your figures'!$B$11
Name In_Relief: 'Your figures'!$B$12
Name In_Extract: 'Your figures'!$B$13
Name MarginalRate: 'Your figures'!$B$15
Name ReducerRate: 'Your figures'!$B$16
Name DivRate: 'Your figures'!$B$17
Name ReliefFlag: 'Your figures'!$B$18
Name RetainFlag: 'Your figures'!$B$19
Name Gain: 'Your figures'!$B$22
Name TaxableGain: 'Your figures'!$B$23
Name UnusedBand: 'Your figures'!$B$24
Name CgtFull: 'Your figures'!$B$25
Name CgtCost: 'Your figures'!$B$26
Name SdltStandard: 'Your figures'!$B$27
Name SdltSurcharge: 'Your figures'!$B$28
Name SdltCost: 'Your figures'!$B$29
Name UpfrontCost: 'Your figures'!$B$30
Name ProfitBeforeFinance: 'Your figures'!$E$22
Name PersBefore: 'Your figures'!$E$23
Name PersCredit: 'Your figures'!$E$24
Name PersonalTax: 'Your figures'!$E$25
Name CoProfit: 'Your figures'!$E$26
Name CoTax: 'Your figures'!$E$27
Name DivTax: 'Your figures'!$E$28
Name CompanyTax: 'Your figures'!$E$29
Name DivDrawn: 'Your figures'!$B$37
Name UnusedPA: 'Your figures'!$B$38

Sheet Rates
A1: Locked rates — do not edit
A2: Income tax — basic rate | B2: 0.2
A3: Income tax — higher rate | B3: 0.4
A4: Income tax — additional rate | B4: 0.45
A5: Section 24 finance-cost credit (2026/27) | B5: 0.2
A6: Section 24 finance-cost credit (2027/28) | B6: 0.22
A7: CGT annual exempt amount (£) | B7: 3000
A8: CGT residential — basic rate | B8: 0.18
A9: CGT residential — higher rate | B9: 0.24
A10: SDLT additional-dwelling surcharge | B10: 0.05
A11: Corporation Tax — small profits rate | B11: 0.19
A12: Corporation Tax — main rate | B12: 0.25
A13: Corporation Tax — lower limit (£) | B13: 50000
... A18: Dividend tax — additional rate | B18: 0.3935
A20: Standard SDLT bands (England & NI)
A21: Lower threshold (£) | B21: Upper threshold (£) | C21: Rate
A22: 0 | B22: 125000 | C22: 0
A23: 125000 | B23: 250000 | C23: 0.02
A24: 250000 | B24: 925000 | C24: 0.05
A25: 925000 | B25: 1500000 | C25: 0.1
A26: 1500000 | B26: 1000000000 | C26: 0.12
A28: Personal allowance (£) | B28: 12570
A29: Basic-rate band, CGT (£) | B29: 37700
A30: Dividend allowance (£) | B30: 500
A31: Top of basic-rate band, total income (£) | B31: 50270
A32: Additional-rate threshold, total income (£) | B32: 125140

Sheet Lookups
A1: Band | B1: IncomeRate | C1: DivRate | E1: Year | F1: Reducer | H1: Relief | I1: Flag | K1: Extraction | L1: Flag
A2: Basic rate (20%) | B2: =Rate_Basic | C2: =Div_Basic | E2: 2026/27 (20% credit) | F2: =Reducer_2026 | H2: No — pay CGT on transfer | I2: 0 | K2: Draw it all out as dividends | L2: 0
A3: Higher rate (40%) | B3: =Rate_Higher | C3: =Div_Higher | E3: 2027/28 (22% credit) | F3: =Reducer_2027 | H3: Yes — s.162 relief claimed | I3: 1 | K3: Retain and reinvest in the company | L3: 1
A4: Additional rate (45%) | B4: =Rate_Additional | C4: =Div_Additional

Sheet Your figures
A1: Your figures — edit the blue cells
A3: Current property value | B3: 300000
A4: Original purchase price (base cost) | B4: 200000
A5: Buying / improvement costs (reduce the gain) | B5: 0
A6: Annual rental income | B6: 24000
A7: Annual mortgage interest | B7: 9000
A8: Other running costs | B8: 3000
A9: Other taxable income (for the CGT band split) | B9: 0
A10: Your income tax band | B10: Higher rate (40%)
A11: Tax year | B11: 2026/27 (20% credit)
A12: Claim s.162 incorporation relief? | B12: No — pay CGT on transfer
A13: Profit you take out of the company | B13: Draw it all out as dividends
A15: Marginal income tax rate | B15: =VLOOKUP(In_Band,Lookups!$A$2:$C$4,2,FALSE)
A16: Section 24 finance-cost credit rate | B16: =VLOOKUP(In_Year,Lookups!$E$2:$F$3,2,FALSE)
A17: Dividend tax rate (your band) | B17: =VLOOKUP(In_Band,Lookups!$A$2:$C$4,3,FALSE)
A18: s.162 relief flag (1 = CGT deferred) | B18: =VLOOKUP(In_Relief,Lookups!$H$2:$I$3,2,FALSE)
A19: Retain-in-company flag (1 = no dividend) | B19: =VLOOKUP(In_Extract,Lookups!$K$2:$L$3,2,FALSE)
A21: Upfront cost — moving the property into a company | D21: Annual tax — stay personal vs company
A22: Chargeable gain (value − base − costs) | B22: =MAX(0,In_Value-In_Base-In_Costs) | D22: Rental profit before interest | E22: =In_Rent-In_Other
A23: Taxable gain (after £3,000 annual exempt amount) | B23: =MAX(0,Gain-CGT_AEA) | D23: Personal income tax before credit | E23: =MAX(0,ProfitBeforeFinance)*MarginalRate
A24: Unused basic-rate band (after other income) | B24: =MAX(0,BasicRateBand-MAX(0,In_OtherIncome-PersonalAllowance)) | D24: Section 24 finance-cost credit (capped) | E24: =MIN(In_Interest,MAX(0,ProfitBeforeFinance))*ReducerRate
A25: CGT on transfer (18% in band, 24% above) | B25: =MIN(TaxableGain,UnusedBand)*CGT_Basic+MAX(0,TaxableGain-UnusedBand)*CGT_Higher | D25: Personal income tax (per year) | E25: =MAX(0,PersBefore-PersCredit)
A26: CGT actually due (£0 if s.162 relief claimed) | B26: =IF(ReliefFlag=1,0,CgtFull) | D26: Company profit (interest deducted in full) | E26: =MAX(0,ProfitBeforeFinance-In_Interest)
A27: SDLT — standard bands (marginal) | B27: =SUMPRODUCT(SDLT_Rates,(MIN(In_Value,SDLT_Uppers)>SDLT_Lowers)*(MIN(In_Value,SDLT_Uppers)-SDLT_Lowers)) | D27: Corporation Tax | E27: =IF(CoProfit<=0,0,IF(CoProfit<=CT_Lower,CoProfit*CT_Small,IF(CoProfit>=CT_Upper,CoProfit*CT_Main,CoProfit*CT_Main-(CT_Upper-CoProfit)*CT_Fraction)))
A28: SDLT — additional-dwelling surcharge (5%) | B28: =In_Value*SDLT_Surcharge | D28: Dividend tax on extracting profit (0 if retained) | E28: =IF(RetainFlag=1,0,DivTaxDetail)
A29: SDLT total | B29: =SdltStandard+SdltSurcharge | D29: Total company tax (CT + dividends, per year) | E29: =CoTax+DivTax
A30: Total upfront cost (CGT + SDLT) | B30: =CgtCost+SdltCost
D31: The decision
D32: Annual saving (personal − company tax) | E32: =PersonalTax-CompanyTax
D33: Break-even (years to recover the upfront cost) | E33: =IF(AnnualSaving>0,UpfrontCost/AnnualSaving,"Never")
D34: Worth incorporating on these figures? | E34: =IF(AnnualSaving>0,"Saves tax each year","No saving")
A36: Dividend tax detail (if you extract profit)
A37: Dividend drawn (post-CT profit) | B37: =MAX(0,CoProfit-CoTax)
A38: Unused personal allowance | B38: =MAX(0,PersonalAllowance-MAX(0,In_OtherIncome))
A39: Other taxable income (above PA) | B39: =MAX(0,In_OtherIncome-PersonalAllowance)
A40: Dividend after PA | B40: =MAX(0,DivDrawn-UnusedPA)
A41: Dividend allowance used (tax-free) | B41: =MIN(DivAfterPA,DividendAllowance)
A42: Taxable dividend | B42: =MAX(0,DivAfterPA-DividendAllowance)
A43: Taxed at basic dividend rate (8.75%) | B43: =MAX(0,MIN(TaxableDiv,(BasicRateTop-PersonalAllowance)-(OtherTaxable+AllowanceUsed)))
A44: Taxed at higher dividend rate (33.75%) | B44: =MAX(0,MIN(TaxableDiv-DivAtBasic,(HigherRateTop-PersonalAllowance)-MAX(OtherTaxable+AllowanceUsed,BasicRateTop-PersonalAllowance)))
...

Sheet Start here
A1: Stay personal vs incorporate — property company model
A3: This spreadsheet weighs the UPFRONT cost of moving a rental property into a limited company
A4: (Capital Gains Tax on the deemed market-value disposal, plus Stamp Duty Land Tax at standard
A5: bands and the 5% additional-dwelling surcharge) against the ANNUAL tax saving the company
A6: structure gives, and works out the break-even point in years.
A8: How to use it:
A9: 1. Go to the 'Your figures' tab.
A10: 2. Edit only the blue cells: property value, base cost, rents, interest, costs, your band, year,
A11: whether you claim s.162 relief, and whether you draw the profit out or reinvest it.
A12: 3. Everything else updates automatically: upfront cost, annual saving, break-even.
A14: The 'Rates' tab holds the locked tax rates and SDLT bands — the same source the website uses.
A15: Read the 'Notes' tab for the assumptions and what this model does NOT cover.

Sheet Notes
A1: Assumptions and limitations
A3: • Upfront cost — Capital Gains Tax. Transferring a property into your own company is a disposal at
A4: market value between connected persons (TCGA 1992 s.17/s.18), so CGT can arise on the gain. This
A5: model applies the £3,000 annual exempt amount, then 18% on the gain within your unused basic-rate
A6: band and 24% above. It assumes the property was never your main home (no Private Residence Relief).
A8: • s.162 incorporation relief can DEFER the CGT where the lettings are a genuine business and ALL the
A9: assets are transferred wholly or partly for shares. Since Finance Act 2026 it must be CLAIMED for
A10: transfers on or after 6 April 2026 (no longer automatic), and HMRC scrutinises whether residential
A11: letting really amounts to a business — usually needing a portfolio under active management. The
A12: relief toggle simply zeroes the CGT; it does not test whether you qualify.
A14: • Upfront cost — SDLT. The company's purchase pays SDLT at standard bands PLUS the 5% additional-
A15: dwelling surcharge on the whole value. A genuine letting company is relieved from the 15% Sch 4A
... A31: tax specialist and model it property by property before acting.
